[2025-05-06T09:06:37.828+0000] {taskinstance.py:1157} INFO - Dependencies all met for dep_context=non-requeueable deps ti=<TaskInstance: example_etl_dag.extract_data manual__2025-05-06T09:01:35.869048+00:00 [queued]>
[2025-05-06T09:06:37.834+0000] {taskinstance.py:1157} INFO - Dependencies all met for dep_context=requeueable deps ti=<TaskInstance: example_etl_dag.extract_data manual__2025-05-06T09:01:35.869048+00:00 [queued]>
[2025-05-06T09:06:37.834+0000] {taskinstance.py:1359} INFO - Starting attempt 2 of 2
[2025-05-06T09:06:37.845+0000] {taskinstance.py:1380} INFO - Executing <Task(PythonOperator): extract_data> on 2025-05-06 09:01:35.869048+00:00
[2025-05-06T09:06:37.851+0000] {standard_task_runner.py:57} INFO - Started process 1413 to run task
[2025-05-06T09:06:37.853+0000] {standard_task_runner.py:84} INFO - Running: ['***', 'tasks', 'run', 'example_etl_dag', 'extract_data', 'manual__2025-05-06T09:01:35.869048+00:00', '--job-id', '5', '--raw', '--subdir', 'DAGS_FOLDER/example_etl_dag.py', '--cfg-path', '/tmp/tmpf2sa7yvb']
[2025-05-06T09:06:37.854+0000] {standard_task_runner.py:85} INFO - Job 5: Subtask extract_data
[2025-05-06T09:06:37.891+0000] {task_command.py:415} INFO - Running <TaskInstance: example_etl_dag.extract_data manual__2025-05-06T09:01:35.869048+00:00 [running]> on host 35e66a92e47e
[2025-05-06T09:06:37.960+0000] {taskinstance.py:1660} INFO - Exporting env vars: AIRFLOW_CTX_DAG_OWNER='***' AIRFLOW_CTX_DAG_ID='example_etl_dag' AIRFLOW_CTX_TASK_ID='extract_data' AIRFLOW_CTX_EXECUTION_DATE='2025-05-06T09:01:35.869048+00:00' AIRFLOW_CTX_TRY_NUMBER='2' AIRFLOW_CTX_DAG_RUN_ID='manual__2025-05-06T09:01:35.869048+00:00'
[2025-05-06T09:06:37.964+0000] {taskinstance.py:1935} ERROR - Task failed with exception
Traceback (most recent call last):
  File "/home/airflow/.local/lib/python3.8/site-packages/urllib3/connection.py", line 174, in _new_conn
    conn = connection.create_connection(
  File "/home/airflow/.local/lib/python3.8/site-packages/urllib3/util/connection.py", line 95, in create_connection
    raise err
  File "/home/airflow/.local/lib/python3.8/site-packages/urllib3/util/connection.py", line 85, in create_connection
    sock.connect(sa)
ConnectionRefusedError: [Errno 111] Connection refused

During handling of the above exception, another exception occurred:

Traceback (most recent call last):
  File "/home/airflow/.local/lib/python3.8/site-packages/urllib3/connectionpool.py", line 714, in urlopen
    httplib_response = self._make_request(
  File "/home/airflow/.local/lib/python3.8/site-packages/urllib3/connectionpool.py", line 415, in _make_request
    conn.request(method, url, **httplib_request_kw)
  File "/home/airflow/.local/lib/python3.8/site-packages/urllib3/connection.py", line 244, in request
    super(HTTPConnection, self).request(method, url, body=body, headers=headers)
  File "/usr/local/lib/python3.8/http/client.py", line 1256, in request
    self._send_request(method, url, body, headers, encode_chunked)
  File "/usr/local/lib/python3.8/http/client.py", line 1302, in _send_request
    self.endheaders(body, encode_chunked=encode_chunked)
  File "/usr/local/lib/python3.8/http/client.py", line 1251, in endheaders
    self._send_output(message_body, encode_chunked=encode_chunked)
  File "/usr/local/lib/python3.8/http/client.py", line 1011, in _send_output
    self.send(msg)
  File "/usr/local/lib/python3.8/http/client.py", line 951, in send
    self.connect()
  File "/home/airflow/.local/lib/python3.8/site-packages/urllib3/connection.py", line 205, in connect
    conn = self._new_conn()
  File "/home/airflow/.local/lib/python3.8/site-packages/urllib3/connection.py", line 186, in _new_conn
    raise NewConnectionError(
urllib3.exceptions.NewConnectionError: <urllib3.connection.HTTPConnection object at 0x798191f08910>: Failed to establish a new connection: [Errno 111] Connection refused

During handling of the above exception, another exception occurred:

Traceback (most recent call last):
  File "/home/airflow/.local/lib/python3.8/site-packages/requests/adapters.py", line 486, in send
    resp = conn.urlopen(
  File "/home/airflow/.local/lib/python3.8/site-packages/urllib3/connectionpool.py", line 798, in urlopen
    retries = retries.increment(
  File "/home/airflow/.local/lib/python3.8/site-packages/urllib3/util/retry.py", line 592, in increment
    raise MaxRetryError(_pool, url, error or ResponseError(cause))
urllib3.exceptions.MaxRetryError: HTTPConnectionPool(host='172.20.0.3', port=9870): Max retries exceeded with url: /webhdfs/v1/user/***/weather_data?op=MKDIRS&user.name=*** (Caused by NewConnectionError('<urllib3.connection.HTTPConnection object at 0x798191f08910>: Failed to establish a new connection: [Errno 111] Connection refused'))

During handling of the above exception, another exception occurred:

Traceback (most recent call last):
  File "/home/airflow/.local/lib/python3.8/site-packages/airflow/operators/python.py", line 192, in execute
    return_value = self.execute_callable()
  File "/home/airflow/.local/lib/python3.8/site-packages/airflow/operators/python.py", line 209, in execute_callable
    return self.python_callable(*self.op_args, **self.op_kwargs)
  File "/opt/airflow/dags/example_etl_dag.py", line 27, in extract_data
    requests.put(mkdir_url)
  File "/home/airflow/.local/lib/python3.8/site-packages/requests/api.py", line 130, in put
    return request("put", url, data=data, **kwargs)
  File "/home/airflow/.local/lib/python3.8/site-packages/requests/api.py", line 59, in request
    return session.request(method=method, url=url, **kwargs)
  File "/home/airflow/.local/lib/python3.8/site-packages/requests/sessions.py", line 589, in request
    resp = self.send(prep, **send_kwargs)
  File "/home/airflow/.local/lib/python3.8/site-packages/requests/sessions.py", line 703, in send
    r = adapter.send(request, **kwargs)
  File "/home/airflow/.local/lib/python3.8/site-packages/requests/adapters.py", line 519, in send
    raise ConnectionError(e, request=request)
requests.exceptions.ConnectionError: HTTPConnectionPool(host='172.20.0.3', port=9870): Max retries exceeded with url: /webhdfs/v1/user/***/weather_data?op=MKDIRS&user.name=*** (Caused by NewConnectionError('<urllib3.connection.HTTPConnection object at 0x798191f08910>: Failed to establish a new connection: [Errno 111] Connection refused'))
[2025-05-06T09:06:37.972+0000] {taskinstance.py:1398} INFO - Marking task as FAILED. dag_id=example_etl_dag, task_id=extract_data, execution_date=20250506T090135, start_date=20250506T090637, end_date=20250506T090637
[2025-05-06T09:06:37.980+0000] {standard_task_runner.py:104} ERROR - Failed to execute job 5 for task extract_data (HTTPConnectionPool(host='172.20.0.3', port=9870): Max retries exceeded with url: /webhdfs/v1/user/***/weather_data?op=MKDIRS&user.name=*** (Caused by NewConnectionError('<urllib3.connection.HTTPConnection object at 0x798191f08910>: Failed to establish a new connection: [Errno 111] Connection refused')); 1413)
[2025-05-06T09:06:38.025+0000] {local_task_job_runner.py:228} INFO - Task exited with return code 1
[2025-05-06T09:06:38.067+0000] {taskinstance.py:2776} INFO - 0 downstream tasks scheduled from follow-on schedule check
