[2025-05-06T01:14:40.337+0000] {taskinstance.py:1157} INFO - Dependencies all met for dep_context=non-requeueable deps ti=<TaskInstance: movielens_ingestion.upload_to_hdfs manual__2025-05-06T01:09:27.363860+00:00 [queued]>
[2025-05-06T01:14:40.349+0000] {taskinstance.py:1157} INFO - Dependencies all met for dep_context=requeueable deps ti=<TaskInstance: movielens_ingestion.upload_to_hdfs manual__2025-05-06T01:09:27.363860+00:00 [queued]>
[2025-05-06T01:14:40.349+0000] {taskinstance.py:1359} INFO - Starting attempt 2 of 2
[2025-05-06T01:14:40.368+0000] {taskinstance.py:1380} INFO - Executing <Task(PythonOperator): upload_to_hdfs> on 2025-05-06 01:09:27.363860+00:00
[2025-05-06T01:14:40.377+0000] {standard_task_runner.py:57} INFO - Started process 485 to run task
[2025-05-06T01:14:40.380+0000] {standard_task_runner.py:84} INFO - Running: ['***', 'tasks', 'run', 'movielens_ingestion', 'upload_to_hdfs', 'manual__2025-05-06T01:09:27.363860+00:00', '--job-id', '63', '--raw', '--subdir', 'DAGS_FOLDER/movielens_ingestion.py', '--cfg-path', '/tmp/tmpql3f5vbn']
[2025-05-06T01:14:40.383+0000] {standard_task_runner.py:85} INFO - Job 63: Subtask upload_to_hdfs
[2025-05-06T01:14:40.402+0000] {logging_mixin.py:151} WARNING - /home/***/.local/lib/python3.8/site-packages/***/settings.py:195 DeprecationWarning: The sql_alchemy_conn option in [core] has been moved to the sql_alchemy_conn option in [database] - the old setting has been used, but please update your config.
[2025-05-06T01:14:40.444+0000] {task_command.py:415} INFO - Running <TaskInstance: movielens_ingestion.upload_to_hdfs manual__2025-05-06T01:09:27.363860+00:00 [running]> on host 7cfed5a894a5
[2025-05-06T01:14:40.547+0000] {taskinstance.py:1660} INFO - Exporting env vars: AIRFLOW_CTX_DAG_OWNER='***' AIRFLOW_CTX_DAG_ID='movielens_ingestion' AIRFLOW_CTX_TASK_ID='upload_to_hdfs' AIRFLOW_CTX_EXECUTION_DATE='2025-05-06T01:09:27.363860+00:00' AIRFLOW_CTX_TRY_NUMBER='2' AIRFLOW_CTX_DAG_RUN_ID='manual__2025-05-06T01:09:27.363860+00:00'
[2025-05-06T01:14:43.609+0000] {taskinstance.py:1935} ERROR - Task failed with exception
Traceback (most recent call last):
  File "/home/airflow/.local/lib/python3.8/site-packages/urllib3/connection.py", line 174, in _new_conn
    conn = connection.create_connection(
  File "/home/airflow/.local/lib/python3.8/site-packages/urllib3/util/connection.py", line 95, in create_connection
    raise err
  File "/home/airflow/.local/lib/python3.8/site-packages/urllib3/util/connection.py", line 85, in create_connection
    sock.connect(sa)
OSError: [Errno 113] No route to host

During handling of the above exception, another exception occurred:

Traceback (most recent call last):
  File "/home/airflow/.local/lib/python3.8/site-packages/urllib3/connectionpool.py", line 714, in urlopen
    httplib_response = self._make_request(
  File "/home/airflow/.local/lib/python3.8/site-packages/urllib3/connectionpool.py", line 415, in _make_request
    conn.request(method, url, **httplib_request_kw)
  File "/home/airflow/.local/lib/python3.8/site-packages/urllib3/connection.py", line 244, in request
    super(HTTPConnection, self).request(method, url, body=body, headers=headers)
  File "/usr/local/lib/python3.8/http/client.py", line 1256, in request
    self._send_request(method, url, body, headers, encode_chunked)
  File "/usr/local/lib/python3.8/http/client.py", line 1302, in _send_request
    self.endheaders(body, encode_chunked=encode_chunked)
  File "/usr/local/lib/python3.8/http/client.py", line 1251, in endheaders
    self._send_output(message_body, encode_chunked=encode_chunked)
  File "/usr/local/lib/python3.8/http/client.py", line 1011, in _send_output
    self.send(msg)
  File "/usr/local/lib/python3.8/http/client.py", line 951, in send
    self.connect()
  File "/home/airflow/.local/lib/python3.8/site-packages/urllib3/connection.py", line 205, in connect
    conn = self._new_conn()
  File "/home/airflow/.local/lib/python3.8/site-packages/urllib3/connection.py", line 186, in _new_conn
    raise NewConnectionError(
urllib3.exceptions.NewConnectionError: <urllib3.connection.HTTPConnection object at 0x7d4ededcf970>: Failed to establish a new connection: [Errno 113] No route to host

During handling of the above exception, another exception occurred:

Traceback (most recent call last):
  File "/home/airflow/.local/lib/python3.8/site-packages/requests/adapters.py", line 486, in send
    resp = conn.urlopen(
  File "/home/airflow/.local/lib/python3.8/site-packages/urllib3/connectionpool.py", line 798, in urlopen
    retries = retries.increment(
  File "/home/airflow/.local/lib/python3.8/site-packages/urllib3/util/retry.py", line 592, in increment
    raise MaxRetryError(_pool, url, error or ResponseError(cause))
urllib3.exceptions.MaxRetryError: HTTPConnectionPool(host='172.20.0.2', port=9870): Max retries exceeded with url: /webhdfs/v1/user/***/movielens?op=MKDIRS&user.name=*** (Caused by NewConnectionError('<urllib3.connection.HTTPConnection object at 0x7d4ededcf970>: Failed to establish a new connection: [Errno 113] No route to host'))

During handling of the above exception, another exception occurred:

Traceback (most recent call last):
  File "/home/airflow/.local/lib/python3.8/site-packages/airflow/operators/python.py", line 192, in execute
    return_value = self.execute_callable()
  File "/home/airflow/.local/lib/python3.8/site-packages/airflow/operators/python.py", line 209, in execute_callable
    return self.python_callable(*self.op_args, **self.op_kwargs)
  File "/opt/airflow/dags/movielens_ingestion.py", line 51, in upload_to_hdfs
    response = requests.put(mkdir_url)
  File "/home/airflow/.local/lib/python3.8/site-packages/requests/api.py", line 130, in put
    return request("put", url, data=data, **kwargs)
  File "/home/airflow/.local/lib/python3.8/site-packages/requests/api.py", line 59, in request
    return session.request(method=method, url=url, **kwargs)
  File "/home/airflow/.local/lib/python3.8/site-packages/requests/sessions.py", line 589, in request
    resp = self.send(prep, **send_kwargs)
  File "/home/airflow/.local/lib/python3.8/site-packages/requests/sessions.py", line 703, in send
    r = adapter.send(request, **kwargs)
  File "/home/airflow/.local/lib/python3.8/site-packages/requests/adapters.py", line 519, in send
    raise ConnectionError(e, request=request)
requests.exceptions.ConnectionError: HTTPConnectionPool(host='172.20.0.2', port=9870): Max retries exceeded with url: /webhdfs/v1/user/***/movielens?op=MKDIRS&user.name=*** (Caused by NewConnectionError('<urllib3.connection.HTTPConnection object at 0x7d4ededcf970>: Failed to establish a new connection: [Errno 113] No route to host'))
[2025-05-06T01:14:43.630+0000] {taskinstance.py:1398} INFO - Marking task as FAILED. dag_id=movielens_ingestion, task_id=upload_to_hdfs, execution_date=20250506T010927, start_date=20250506T011440, end_date=20250506T011443
[2025-05-06T01:14:43.649+0000] {standard_task_runner.py:104} ERROR - Failed to execute job 63 for task upload_to_hdfs (HTTPConnectionPool(host='172.20.0.2', port=9870): Max retries exceeded with url: /webhdfs/v1/user/***/movielens?op=MKDIRS&user.name=*** (Caused by NewConnectionError('<urllib3.connection.HTTPConnection object at 0x7d4ededcf970>: Failed to establish a new connection: [Errno 113] No route to host')); 485)
[2025-05-06T01:14:43.685+0000] {local_task_job_runner.py:228} INFO - Task exited with return code 1
[2025-05-06T01:14:43.720+0000] {taskinstance.py:2776} INFO - 0 downstream tasks scheduled from follow-on schedule check
