[2025-05-05T23:10:46.365+0000] {taskinstance.py:1157} INFO - Dependencies all met for dep_context=non-requeueable deps ti=<TaskInstance: movielens_ingestion.upload_to_hdfs scheduled__2025-05-04T22:10:32.990363+00:00 [queued]>
[2025-05-05T23:10:46.375+0000] {taskinstance.py:1157} INFO - Dependencies all met for dep_context=requeueable deps ti=<TaskInstance: movielens_ingestion.upload_to_hdfs scheduled__2025-05-04T22:10:32.990363+00:00 [queued]>
[2025-05-05T23:10:46.376+0000] {taskinstance.py:1359} INFO - Starting attempt 2 of 2
[2025-05-05T23:10:46.391+0000] {taskinstance.py:1380} INFO - Executing <Task(PythonOperator): upload_to_hdfs> on 2025-05-04 22:10:32.990363+00:00
[2025-05-05T23:10:46.398+0000] {standard_task_runner.py:57} INFO - Started process 1425 to run task
[2025-05-05T23:10:46.400+0000] {standard_task_runner.py:84} INFO - Running: ['***', 'tasks', 'run', 'movielens_ingestion', 'upload_to_hdfs', 'scheduled__2025-05-04T22:10:32.990363+00:00', '--job-id', '33', '--raw', '--subdir', 'DAGS_FOLDER/movielens_ingestion.py', '--cfg-path', '/tmp/tmpl8x5sw6t']
[2025-05-05T23:10:46.402+0000] {standard_task_runner.py:85} INFO - Job 33: Subtask upload_to_hdfs
[2025-05-05T23:10:46.418+0000] {logging_mixin.py:151} WARNING - /home/***/.local/lib/python3.8/site-packages/***/settings.py:195 DeprecationWarning: The sql_alchemy_conn option in [core] has been moved to the sql_alchemy_conn option in [database] - the old setting has been used, but please update your config.
[2025-05-05T23:10:46.452+0000] {task_command.py:415} INFO - Running <TaskInstance: movielens_ingestion.upload_to_hdfs scheduled__2025-05-04T22:10:32.990363+00:00 [running]> on host 56aa4ba7abee
[2025-05-05T23:10:46.538+0000] {taskinstance.py:1660} INFO - Exporting env vars: AIRFLOW_CTX_DAG_OWNER='***' AIRFLOW_CTX_DAG_ID='movielens_ingestion' AIRFLOW_CTX_TASK_ID='upload_to_hdfs' AIRFLOW_CTX_EXECUTION_DATE='2025-05-04T22:10:32.990363+00:00' AIRFLOW_CTX_TRY_NUMBER='2' AIRFLOW_CTX_DAG_RUN_ID='scheduled__2025-05-04T22:10:32.990363+00:00'
[2025-05-05T23:10:46.540+0000] {client.py:192} INFO - Instantiated <InsecureClient(url='http://172.20.0.2:50070')>.
[2025-05-05T23:10:46.540+0000] {client.py:1028} INFO - Creating directories to '/user/***/movielens'.
[2025-05-05T23:11:47.154+0000] {local_task_job_runner.py:294} WARNING - State of this instance has been externally set to None. Terminating instance.
[2025-05-05T23:11:47.157+0000] {process_utils.py:131} INFO - Sending 15 to group 1425. PIDs of all processes in the group: [1425]
[2025-05-05T23:11:47.157+0000] {process_utils.py:86} INFO - Sending the signal 15 to group 1425
[2025-05-05T23:11:47.157+0000] {taskinstance.py:1630} ERROR - Received SIGTERM. Terminating subprocesses.
[2025-05-05T23:11:47.166+0000] {taskinstance.py:1935} ERROR - Task failed with exception
Traceback (most recent call last):
  File "/home/airflow/.local/lib/python3.8/site-packages/airflow/operators/python.py", line 192, in execute
    return_value = self.execute_callable()
  File "/home/airflow/.local/lib/python3.8/site-packages/airflow/operators/python.py", line 209, in execute_callable
    return self.python_callable(*self.op_args, **self.op_kwargs)
  File "/opt/airflow/dags/movielens_ingestion.py", line 46, in upload_to_hdfs
    client.makedirs(hdfs_path)
  File "/home/airflow/.local/lib/python3.8/site-packages/hdfs/client.py", line 1029, in makedirs
    self._mkdirs(hdfs_path, permission=permission)
  File "/home/airflow/.local/lib/python3.8/site-packages/hdfs/client.py", line 102, in api_handler
    res = client._request(
  File "/home/airflow/.local/lib/python3.8/site-packages/hdfs/client.py", line 209, in _request
    return self._session.request(
  File "/home/airflow/.local/lib/python3.8/site-packages/requests/sessions.py", line 589, in request
    resp = self.send(prep, **send_kwargs)
  File "/home/airflow/.local/lib/python3.8/site-packages/requests/sessions.py", line 703, in send
    r = adapter.send(request, **kwargs)
  File "/home/airflow/.local/lib/python3.8/site-packages/requests/adapters.py", line 486, in send
    resp = conn.urlopen(
  File "/home/airflow/.local/lib/python3.8/site-packages/urllib3/connectionpool.py", line 714, in urlopen
    httplib_response = self._make_request(
  File "/home/airflow/.local/lib/python3.8/site-packages/urllib3/connectionpool.py", line 415, in _make_request
    conn.request(method, url, **httplib_request_kw)
  File "/home/airflow/.local/lib/python3.8/site-packages/urllib3/connection.py", line 244, in request
    super(HTTPConnection, self).request(method, url, body=body, headers=headers)
  File "/usr/local/lib/python3.8/http/client.py", line 1256, in request
    self._send_request(method, url, body, headers, encode_chunked)
  File "/usr/local/lib/python3.8/http/client.py", line 1302, in _send_request
    self.endheaders(body, encode_chunked=encode_chunked)
  File "/usr/local/lib/python3.8/http/client.py", line 1251, in endheaders
    self._send_output(message_body, encode_chunked=encode_chunked)
  File "/usr/local/lib/python3.8/http/client.py", line 1011, in _send_output
    self.send(msg)
  File "/usr/local/lib/python3.8/http/client.py", line 951, in send
    self.connect()
  File "/home/airflow/.local/lib/python3.8/site-packages/urllib3/connection.py", line 205, in connect
    conn = self._new_conn()
  File "/home/airflow/.local/lib/python3.8/site-packages/urllib3/connection.py", line 174, in _new_conn
    conn = connection.create_connection(
  File "/home/airflow/.local/lib/python3.8/site-packages/urllib3/util/connection.py", line 85, in create_connection
    sock.connect(sa)
  File "/home/airflow/.local/lib/python3.8/site-packages/airflow/models/taskinstance.py", line 1632, in signal_handler
    raise AirflowException("Task received SIGTERM signal")
airflow.exceptions.AirflowException: Task received SIGTERM signal
[2025-05-05T23:11:47.173+0000] {taskinstance.py:1398} INFO - Marking task as FAILED. dag_id=movielens_ingestion, task_id=upload_to_hdfs, execution_date=20250504T221032, start_date=20250505T231046, end_date=20250505T231147
[2025-05-05T23:11:47.187+0000] {standard_task_runner.py:104} ERROR - Failed to execute job 33 for task upload_to_hdfs ((psycopg2.errors.ForeignKeyViolation) insert or update on table "task_fail" violates foreign key constraint "task_fail_ti_fkey"
DETAIL:  Key (dag_id, task_id, run_id, map_index)=(movielens_ingestion, upload_to_hdfs, scheduled__2025-05-04T22:10:32.990363+00:00, -1) is not present in table "task_instance".

[SQL: INSERT INTO task_fail (task_id, dag_id, run_id, map_index, start_date, end_date, duration) VALUES (%(task_id)s, %(dag_id)s, %(run_id)s, %(map_index)s, %(start_date)s, %(end_date)s, %(duration)s) RETURNING task_fail.id]
[parameters: {'task_id': 'upload_to_hdfs', 'dag_id': 'movielens_ingestion', 'run_id': 'scheduled__2025-05-04T22:10:32.990363+00:00', 'map_index': -1, 'start_date': datetime.datetime(2025, 5, 5, 23, 10, 46, 366296, tzinfo=Timezone('UTC')), 'end_date': datetime.datetime(2025, 5, 5, 23, 11, 47, 172812, tzinfo=Timezone('UTC')), 'duration': 60}]
(Background on this error at: https://sqlalche.me/e/14/gkpj); 1425)
[2025-05-05T23:11:47.209+0000] {process_utils.py:79} INFO - Process psutil.Process(pid=1425, status='terminated', exitcode=1, started='23:10:46') (1425) terminated with exit code 1
